<?xml version="1.0"?>

<robot xmlns:xacro="http://www.ros.org/wiki/xacro" name="Arm">
    <link name="base_link">
        <visual>
            <origin xyz="0.0 0.0 0.0" rpy="1.57 0.0 0.0"/>
            <geometry>
                <mesh filename="package://arm/meshes/Circular_Base.STL" scale="0.01 0.01 0.01"/>
            </geometry>
        </visual>

        <collision>
            <origin xyz="0.0 0.0 0.0" rpy="0.0 0.0 0.0"/>
            <geometry>
                <mesh filename="package://arm/meshes/Circular_Base.STL" scale="0.01 0.01 0.01"/>
            </geometry>
        </collision>

    </link>
    <link name="shoulder">
        <visual>
            <origin xyz="0.0 0.0 0.0" rpy="1.57 0.0 0.0"/>
            <geometry>
                <mesh filename="package://arm/meshes/Shoulder.STL" scale="0.01 0.01 0.01"/>
            </geometry>
        </visual>

        <collision>
            <origin xyz="0.0 0.0 0.0" rpy="0.0 0.0 0.0"/>
            <geometry>
                <mesh filename="package://arm/meshes/Shoulder.STL" scale="0.01 0.01 0.01"/>
            </geometry>
        </collision>
    </link>

    <joint name="Shoulder" type="revolute">
        <origin xyz="0.0 0.0 0.5" rpy="0.0 0.0 0.0"/>
        <parent link="base_link"/>
        <child link="shoulder"/>
        <axis xyz="0.0 0.0 1.0"/>
        <limit lower="-1.57" upper="1.57" effort="1.0" velocity="1.0"/>
    </joint>
</robot>